Workbook

Sheet Matriz
A1: MATRIZ DE EVALUACIÓN DE PROBLEMAS — METODOLOGÍA SMART
A2: Proyecto Integrador en Inteligencia Artificial · Jairo Wladimir Jhayya Perlaza · Escala: 1 = Muy bajo, 5 = Excelente · Puntajes en azul = valores asignados; en negro = fórmulas
A4: Criterio de evaluación | B4: Problema 1 Ciberseguridad (tráfico de red cifrado) | C4: Problema 2 Agricultura (plagas en cultivos) | D4: Problema 3 Finanzas (fraude transaccional) | E4: Peso
A5: ESPECÍFICO (1-5) | B5: 4 | C5: 4 | D5: 3 | E5: 0.2
A6: MEDIBLE (1-5) | B6: 5 | C6: 4 | D6: 5 | E6: 0.2
A7: ALCANZABLE (1-5) | B7: 4 | C7: 3 | D7: 4 | E7: 0.25
A8: RELEVANTE (1-5) | B8: 5 | C8: 5 | D8: 4 | E8: 0.2
A9: TEMPORAL (1-5) | B9: 4 | C9: 3 | D9: 5 | E9: 0.15
A10: TOTAL PONDERADO (sobre 5) | B10: =SUMPRODUCT(B5:B9,$E$5:$E$9) -> 4.4 | C10: =SUMPRODUCT(C5:C9,$E$5:$E$9) -> 3.8 | D10: =SUMPRODUCT(D5:D9,$E$5:$E$9) -> 4.15 | E10: =SUM(E5:E9) -> 1
A11: Porcentaje de cumplimiento | B11: =B10/5 -> 0.88 | C11: =C10/5 -> 0.76 | D11: =D10/5 -> 0.83
A12: Posición en el ranking | B12: =RANK(B10,$B$10:$D$10) -> 1 | C12: =RANK(C10,$B$10:$D$10) -> 3 | D12: =RANK(D10,$B$10:$D$10) -> 2
A14: PROBLEMA SELECCIONADO | B14: =SUBSTITUTE(INDEX($B$4:$D$4,MATCH(MAX($B$10:$D$10),$B$10:$D$10,0)),CHAR(10)," ") -> Problema 1 Ciberseguridad (tráfico de red cifrado)
A16: CONTRIBUCIÓN PONDERADA POR CRITERIO (puntaje × peso)
A17: Criterio | B17: Problema 1 | C17: Problema 2 | D17: Problema 3 | E17: Peso
A18: =A5 -> ESPECÍFICO (1-5) | B18: =B5*$E$5 -> 0.8 | C18: =C5*$E$5 -> 0.8 | D18: =D5*$E$5 -> 0.6 | E18: =E5 -> 0.2
A19: =A6 -> MEDIBLE (1-5) | B19: =B6*$E$6 -> 1 | C19: =C6*$E$6 -> 0.8 | D19: =D6*$E$6 -> 1 | E19: =E6 -> 0.2
A20: =A7 -> ALCANZABLE (1-5) | B20: =B7*$E$7 -> 1 | C20: =C7*$E$7 -> 0.75 | D20: =D7*$E$7 -> 1 | E20: =E7 -> 0.25
A21: =A8 -> RELEVANTE (1-5) | B21: =B8*$E$8 -> 1 | C21: =C8*$E$8 -> 1 | D21: =D8*$E$8 -> 0.8 | E21: =E8 -> 0.2
A22: =A9 -> TEMPORAL (1-5) | B22: =B9*$E$9 -> 0.6 | C22: =C9*$E$9 -> 0.45 | D22: =D9*$E$9 -> 0.75 | E22: =E9 -> 0.15
A23: Suma (verificación = total ponderado) | B23: =SUM(B18:B22) -> 4.4 | C23: =SUM(C18:C22) -> 3.8 | D23: =SUM(D18:D22) -> 4.15 | E23: =SUM(E18:E22) -> 1
A25: Nota metodológica: los puntajes evalúan los problemas tal como fueron publicados en el foro académico. El criterio TEMPORAL se valoró considerando el horizonte efectivo del proyecto integrador (6 semanas, según la consigna del foro), más exigente que las 16 semanas de referencia del instructivo. Los puntajes se apoyaron en el Canvas SMART (hoja «Canvas SMART») y sus justificaciones y evidencias están en la hoja «Justificaciones».

Sheet Justificaciones
A1: JUSTIFICACIÓN Y EVIDENCIA DE CADA PUNTAJE
A3: Criterio | B3: Problema | C3: Puntaje | D3: Justificación (50-80 palabras) | E3: Evidencia del foro académico | F3: Nº palabras | G3: Campo del Canvas SMART de apoyo
A4: ESPECÍFICO | B4: P1 — Ciberseguridad | C4: =Matriz!B5 -> 4 | D4: El problema está bien delimitado en su contexto: tráfico cifrado con TLS 1.3 y QUIC que inutiliza la inspección profunda de paquetes, y nombra stakeholders concretos (empresas, proveedores de Internet y equipos de seguridad). Pierde un punto porque mezcla dos tareas distintas —clasificación de tráfico y detección de intrusiones— y dos datasets de naturaleza diferente (CIC-IDS2017 y CESNET-TLS22), lo que deja ambiguo el objetivo concreto del proyecto. | E4: Foro, Problema 1: «La clasificación de tráfico de red cifrado para detección de intrusiones» y «entrenado sobre datasets públicos como CIC-IDS2017 o CESNET-TLS22». | F4: =LEN(TRIM(D4))-LEN(SUBSTITUTE(TRIM(D4)," ",""))+1 -> 67 | G4: Canvas S: qué construir, tipo de solución IA, funcionalidades y usuarios
A5: ESPECÍFICO | B5: P2 — Agricultura | C5: =Matriz!C5 -> 4 | D5: Define con claridad el problema (detección tardía de plagas), los afectados (pequeños y medianos productores) y los cultivos de interés (banano, cacao y arroz), además de la barrera de acceso a asesoría agronómica. Pierde un punto porque combina tres cultivos distintos y dos tareas —identificar la enfermedad y estimar su severidad—, lo que dispersa el alcance y dificulta precisar un objetivo único y verificable. | E5: Foro, Problema 2: «pequeños y medianos productores agrícolas (banano, cacao, arroz)» e «identifique la enfermedad y su nivel de severidad». | F5: =LEN(TRIM(D5))-LEN(SUBSTITUTE(TRIM(D5)," ",""))+1 -> 64 | G5: Canvas S: qué construir, tipo de solución IA, funcionalidades y usuarios
A6: ESPECÍFICO | B6: P3 — Finanzas | C6: =Matriz!D5 -> 3 | D6: Identifica afectados concretos (usuarios, comercios, entidades financieras y usuarios recién bancarizados), pero agrupa bajo «fraude» fenómenos distintos: phishing, apropiación de cuentas y transacciones no autorizadas, que requieren datos y modelos diferentes. Además, el problema se plantea para banca y billeteras electrónicas, mientras la fuente de datos propuesta es de tarjetas de crédito, lo que desalinea el objetivo con los datos disponibles. | E6: Foro, Problema 3: «(phishing, apropiación de cuentas, transacciones no autorizadas)» y «datasets públicos de fraude con tarjetas de crédito». | F6: =LEN(TRIM(D6))-LEN(SUBSTITUTE(TRIM(D6)," ",""))+1 -> 61 | G6: Canvas S: qué construir, tipo de solución IA, funcionalidades y usuarios
A7: MEDIBLE | B7: P1 — Ciberseguridad | C7: =Matriz!B6 -> 5 | D7: Es el problema con métricas más estandarizadas: la clasificación sobre datasets etiquetados permite cuantificar F1-score macro y ponderado, exactitud, matriz de confusión y tasa de falsos positivos, todas comparables con la literatura. Además admite KPIs de costo operativo, como la latencia de inferencia por flujo, relevante para un proveedor de red. Los resultados son reproducibles porque los datasets mencionados tienen etiquetas públicas. | E7: Foro, Problema 1: «un modelo de aprendizaje profundo que clasifique flujos», entrenado sobre datasets públicos etiquetados. | F7: =LEN(TRIM(D7))-LEN(SUBSTITUTE(TRIM(D7)," ",""))+1 -> 62 | G7: Canvas M: métricas técnicas, métricas de negocio y baseline actual
A8: MEDIBLE | B8: P2 — Agricultura | C8: =Matriz!C6 -> 4 | D8: La identificación de enfermedades es un problema de clasificación de imágenes con métricas claras: exactitud, F1-score por clase y matriz de confusión. Como KPI de impacto podría medirse el tiempo de diagnóstico frente a la consulta agronómica tradicional. Recibe cuatro puntos porque la estimación de severidad es difícil de cuantificar: requiere imágenes etiquetadas por grado de afectación, que los datasets públicos generalmente no ofrecen. | E8: Foro, Problema 2: «identifique la enfermedad y su nivel de severidad». | F8: =LEN(TRIM(D8))-LEN(SUBSTITUTE(TRIM(D8)," ",""))+1 -> 64 | G8: Canvas M: métricas técnicas, métricas de negocio y baseline actual
A9: MEDIBLE | B9: P3 — Finanzas | C9: =Matriz!D6 -> 5 | D9: La detección de fraude cuenta con métricas maduras y adecuadas al desbalance extremo de clases: precisión, recall, F1-score y área bajo la curva precisión-recall (AUPRC). También admite KPIs de negocio, como la proporción de fraude detectado o el costo que los falsos positivos generan al cliente legítimo. Los resultados son completamente cuantificables sobre datasets etiquetados y comparables con trabajos previos. | E9: Foro, Problema 3: «aplicando técnicas para manejar el desbalance de clases». | F9: =LEN(TRIM(D9))-LEN(SUBSTITUTE(TRIM(D9)," ",""))+1 -> 60 | G9: Canvas M: métricas técnicas, métricas de negocio y baseline actual
A10: ALCANZABLE | B10: P1 — Ciberseguridad | C10: =Matriz!B7 -> 4 | D10: Los datos son públicos y de acceso libre, y trabajar con características de flujo no requiere inspeccionar contenido ni gestionar datos personales. Las técnicas son apropiadas para el nivel de maestría. No alcanza el máximo porque el foro plantea aprendizaje profundo, que exige GPU (resoluble con Google Colab o Kaggle), y porque CESNET-TLS22 completo es muy voluminoso, lo que obliga a trabajar con una muestra reducida. | E10: Foro, Problema 1: «Con un modelo de aprendizaje profundo» y «datasets públicos como CIC-IDS2017 o CESNET-TLS22». | F10: =LEN(TRIM(D10))-LEN(SUBSTITUTE(TRIM(D10)," ",""))+1 -> 66 | G10: Canvas A: recursos humanos, datos, infraestructura, presupuesto y riesgos
A11: ALCANZABLE | B11: P2 — Agricultura | C11: =Matriz!C7 -> 3 | D11: Las técnicas propuestas (redes convolucionales y transfer learning) son apropiadas y accesibles. Sin embargo, PlantVillage no incluye banano, cacao ni arroz, por lo que el proyecto dependería casi por completo de imágenes locales que deben recolectarse y etiquetarse con validación de un especialista. Además, PlantVillage está fotografiado con fondos controlados, lo que suele degradar el desempeño con fotos tomadas directamente en campo. | E11: Foro, Problema 2: «entrenado con datasets públicos como PlantVillage y complementado con imágenes locales». | F11: =LEN(TRIM(D11))-LEN(SUBSTITUTE(TRIM(D11)," ",""))+1 -> 62 | G11: Canvas A: recursos humanos, datos, infraestructura, presupuesto y riesgos
A12: ALCANZABLE | B12: P3 — Finanzas | C12: =Matriz!D7 -> 4 | D12: Es técnicamente muy viable: existen datasets públicos livianos de fraude con tarjetas y modelos como XGBoost entrenan en una laptop en minutos. Pierde un punto porque los datos públicos más utilizados están anonimizados mediante transformaciones que ocultan el significado de las variables, limitando la interpretabilidad, y porque el acceso a datos transaccionales reales de entidades ecuatorianas es prácticamente inviable por confidencialidad. | E12: Foro, Problema 3: «ensambles como XGBoost o redes neuronales» y «datasets públicos de fraude con tarjetas de crédito». | F12: =LEN(TRIM(D12))-LEN(SUBSTITUTE(TRIM(D12)," ",""))+1 -> 61 | G12: Canvas A: recursos humanos, datos, infraestructura, presupuesto y riesgos
A13: RELEVANTE | B13: P1 — Ciberseguridad | C13: =Matriz!B8 -> 5 | D13: Resuelve una necesidad actual y creciente: la mayor parte del tráfico de Internet viaja cifrado y las herramientas de inspección tradicionales pierden efectividad, afectando la gestión y la seguridad de redes empresariales y de proveedores. Está plenamente alineado con tendencias actuales de IA, como las arquitecturas basadas en atención aplicadas al análisis de tráfico, y equilibra seguridad con privacidad al no requerir descifrar las comunicaciones. | E13: Foro, Problema 1: «más del 90% del tráfico de Internet viaja cifrado» y «sin romper el cifrado ni vulnerar la privacidad del usuario». | F13: =LEN(TRIM(D13))-LEN(SUBSTITUTE(TRIM(D13)," ",""))+1 -> 65 | G13: Canvas R: problema de negocio, alineación, prioridad y justificación de IA
A14: RELEVANTE | B14: P2 — Agricultura | C14: =Matriz!C8 -> 5 | D14: Tiene alto impacto económico y social: el banano y el cacao figuran entre los principales productos de exportación del Ecuador, y los pequeños productores son los más vulnerables a pérdidas por plagas. El cambio climático altera los ciclos de las plagas y la amplia disponibilidad de teléfonos inteligentes en zonas rurales hace factible una solución de campo, alineada con la visión por computador en dispositivos móviles. | E14: Foro, Problema 2: «presión del cambio climático» y «disponibilidad masiva de teléfonos inteligentes en zonas rurales». | F14: =LEN(TRIM(D14))-LEN(SUBSTITUTE(TRIM(D14)," ",""))+1 -> 66 | G14: Canvas R: problema de negocio, alineación, prioridad y justificación de IA
A15: RELEVANTE | B15: P3 — Finanzas | C15: =Matriz!D8 -> 4 | D15: Es un problema real con impacto económico directo y relevante para la inclusión financiera en Latinoamérica. Recibe cuatro puntos porque es uno de los problemas más explorados en la literatura de aprendizaje automático, lo que reduce el margen de aporte, y porque los datasets públicos disponibles no reflejan el contexto latinoamericano ni el ecosistema de billeteras electrónicas que motiva la propuesta publicada en el foro. | E15: Foro, Problema 3: «la inclusión financiera digital se aceleró en los últimos años en Latinoamérica». | F15: =LEN(TRIM(D15))-LEN(SUBSTITUTE(TRIM(D15)," ",""))+1 -> 65 | G15: Canvas R: problema de negocio, alineación, prioridad y justificación de IA
A16: TEMPORAL | B16: P1 — Ciberseguridad | C16: =Matriz!B9 -> 4 | D16: Con datasets preprocesados y modelos entrenables en horas, admite hitos claros: preparación de datos, modelos de referencia, modelos profundos, evaluación y aplicación de demostración. Es completable dentro del horizonte del proyecto integrador. Recibe cuatro y no cinco porque, tal como está redactado en el foro, abarcar dos tareas y dos datasets pondría en riesgo el cronograma; requiere acotarse a una sola tarea. | E16: Foro, Problema 1: doble tarea («clasificación de tráfico… para detección de intrusiones») y doble dataset («CIC-IDS2017 o CESNET-TLS22»). | F16: =LEN(TRIM(D16))-LEN(SUBSTITUTE(TRIM(D16)," ",""))+1 -> 62 | G16: Canvas T: fechas, duración, hitos y dependencias
A17: TEMPORAL | B17: P2 — Agricultura | C17: =Matriz!C9 -> 3 | D17: El entrenamiento con transfer learning es rápido, pero el cronograma depende de actividades fuera del control del estudiante: recolección de imágenes en campo, estacionalidad de los cultivos y disponibilidad de un agrónomo para validar etiquetas. Estos hitos son difíciles de garantizar en el horizonte del proyecto, lo que vuelve el cronograma poco realista si no se reduce a un solo cultivo con dataset existente. | E17: Foro, Problema 2: «complementado con imágenes locales». | F17: =LEN(TRIM(D17))-LEN(SUBSTITUTE(TRIM(D17)," ",""))+1 -> 64 | G17: Canvas T: fechas, duración, hitos y dependencias
A18: TEMPORAL | B18: P3 — Finanzas | C18: =Matriz!D9 -> 5 | D18: Es el problema más sencillo de cronogramar: datos listos para usar, entrenamiento rápido y ciclos de experimentación cortos. Admite hitos claros —análisis exploratorio, manejo del desbalance, comparación de modelos, evaluación y demostración— y es completable con holgura dentro del horizonte del proyecto integrador, sin dependencias externas como la recolección de datos en campo o la validación de expertos. | E18: Foro, Problema 3: «entrenados sobre datasets públicos de fraude con tarjetas de crédito». | F18: =LEN(TRIM(D18))-LEN(SUBSTITUTE(TRIM(D18)," ",""))+1 -> 58 | G18: Canvas T: fechas, duración, hitos y dependencias
A20: Puntaje en verde = vínculo a la hoja «Matriz» (fuente única). Nº palabras = verificación automática del rango 50-80 exigido. Los puntajes se apoyaron en el Canvas SMART (hoja «Canvas SMART»).

Sheet Canvas SMART
A1: CANVAS SMART PARA PROYECTOS DE IA — APOYO A LA MATRIZ DE EVALUACIÓN
A2: Los problemas 2 y 3 se desarrollan a partir de lo publicado en el foro. El problema 1 ya incorpora los ajustes detectados al aplicar el Checklist (ver hojas «Checklist P1» y «Refinamiento P1»).
A4: Campo del Canvas | B4: Problema 1 — Ciberseguridad (versión refinada) | C4: Problema 2 — Agricultura | D4: Problema 3 — Finanzas
A5: INFORMACIÓN DEL PROYECTO
A6: Nombre del proyecto | B6: Clasificación de tráfico de red cifrado con aprendizaje automático y Transformers (CESNET-TLS-Year22) | C6: Detección de plagas y enfermedades en cultivos mediante imágenes | D6: Detección de fraude en transacciones digitales
A7: Fecha | B7: 22/09/2026 | C7: 22/09/2026 | D7: 22/09/2026
A8: Equipo | B8: Jairo Wladimir Jhayya Perlaza (individual) | C8: Jairo Wladimir Jhayya Perlaza (individual) | D8: Jairo Wladimir Jhayya Perlaza (individual)
A9: Sponsor / stakeholder principal | B9: Proveedores de Internet y áreas de TI y seguridad de empresas | C9: Pequeños y medianos productores de banano, cacao y arroz | D9: Entidades financieras y operadores de billeteras electrónicas
A10: S — ESPECÍFICO: ¿Qué exactamente vamos a construir/lograr?
A11: Qué se construirá | B11: Estudio comparativo de cuatro modelos y una aplicación web que clasifica flujos cifrados en 24 categorías de servicio | C11: Modelo de visión que identifica la enfermedad y su severidad a partir de fotos de hojas | D11: Clasificador que marca transacciones potencialmente fraudulentas
A12: Tipo de solución IA | B12: ☑ Machine Learning Supervisado ☑ Deep Learning | C12: ☑ Computer Vision ☑ Deep Learning | D12: ☑ Machine Learning Supervisado
A13: Descripción específica | B13: Clasificación por metadatos de flujo (primeros 30 paquetes y estadísticas), sin inspeccionar contenido, con partición temporal de los datos | C13: Red convolucional con transfer learning sobre PlantVillage, complementada con imágenes locales | D13: Ensambles (XGBoost) o redes neuronales sobre variables transaccionales, con manejo del desbalance de clases
A14: Funcionalidades principales | B14: Explorador de datos, arena comparativa de modelos, clasificador en vivo y carga de CSV con plantilla | C14: Captura de foto, diagnóstico, nivel de severidad y recomendación básica | D14: Puntaje de riesgo por transacción, alertas y panel de métricas
A15: Usuarios primarios | B15: Administradores y analistas de red | C15: Productores agrícolas | D15: Analistas antifraude
A16: Usuarios secundarios | B16: Investigadores y docentes de redes e IA | C16: Técnicos y asociaciones agrícolas | D16: Usuarios finales y comercios
A17: M — MEDIBLE: ¿Cómo mediremos el éxito?
A18: Precisión / Accuracy | B18: Se reporta como métrica secundaria, sin meta propia | C18: ≥ 90 % sobre PlantVillage; por medir en campo | D18: No se usa como métrica principal por el desbalance extremo
A19: Recall / Sensibilidad | B19: Reportado por clase | C19: ≥ 85 % por enfermedad | D19: ≥ 80 % sobre transacciones fraudulentas
A20: F1-Score | B20: F1 macro ≥ 80 % (métrica principal) | C20: F1 macro ≥ 85 % | D20: F1 ≥ 80 % y AUPRC ≥ 0,80
A21: Tiempo de respuesta | B21: ≤ 10 ms por flujo en CPU | C21: ≤ 2 s por imagen | D21: ≤ 50 ms por transacción
A22: Throughput | B22: No se mide por separado; se reporta la latencia de inferencia por flujo | C22: No crítico | D22: ≥ 100 transacciones/s
A23: Disponibilidad | B23: Demo pública durante evaluación y sustentación | C23: Prototipo académico | D23: Prototipo académico
A24: ROI / reducción de costos / ingresos | B24: No calculable: prototipo académico sin datos operativos reales | C24: Reducción de pérdidas de cosecha (no cuantificable sin datos de campo) | D24: Reducción de pérdidas por fraude (no cuantificable con datos públicos)
A25: Ahorro de tiempo | B25: Costo computacional relativo de cada modelo (entrenamiento e inferencia) | C25: Diagnóstico inmediato frente a la espera de una visita técnica | D25: Menos revisiones manuales de falsos positivos
A26: Mejora en satisfacción (NPS/CSAT) | B26: No aplica en el alcance | C26: No aplica en el alcance | D26: No aplica en el alcance
A27: Baseline — situación actual | B27: La DPI y las reglas por puerto no funcionan sobre tráfico cifrado | C27: Diagnóstico visual tardío o dependiente de la visita de un agrónomo | D27: Reglas estáticas antifraude
A28: Baseline — métricas actuales | B28: Línea base Random Forest, medida en la semana 1 del proyecto | C28: Sin registros locales | D28: Línea base de regresión logística sobre el dataset
A29: A — ALCANZABLE: ¿Tenemos los recursos y capacidades necesarias?
A30: Recursos humanos | B30: 1 persona (autor) cubre data science, ML engineering y desarrollo; experiencia propia en ciberseguridad y redes | C30: 1 persona (autor) más 1 agrónomo validador, aún no asegurado | D30: 1 persona (autor) cubre data science, ML engineering y desarrollo
A31: Datos disponibles | B31: ☑ Suficientes (>10K registros): millones de flujos etiquetados | C31: ☑ Requiere recolección adicional: PlantVillage no incluye banano, cacao ni arroz | D31: ☑ Suficientes (>10K registros)
A32: Calidad de datos | B32: ☑ Alta: red de producción real, etiquetado por SNI | C32: ☑ Media: imágenes con fondo de laboratorio | D32: ☑ Media: variables anonimizadas
A33: Infraestructura | B33: ☑ Híbrida: laptop, Google Colab/Kaggle y Hugging Face Spaces | C33: ☑ Cloud: GPU para entrenamiento | D33: ☑ Híbrida: laptop y despliegue en la nube
A34: Herramientas / plataformas | B34: VS Code, Python 3.11, cesnet-datazoo, scikit-learn, XGBoost, PyTorch, Streamlit, Docker, GitHub | C34: Python, PyTorch o TensorFlow, aplicación móvil o web | D34: Python, scikit-learn, XGBoost, imbalanced-learn
A35: Presupuesto | B35: USD 0: código abierto y niveles gratuitos de Colab, Kaggle y Hugging Face | C35: Requiere presupuesto para salidas de campo y validación experta (no estimado) | D35: USD 0: código abierto y dataset público
A36: Riesgos técnicos identificados | B36: Tamaño de la descarga del dataset, convergencia del Transformer, límites de sesión de Colab y falla del despliegue | C36: Recolección de imágenes, estacionalidad y baja generalización de laboratorio a campo | D36: Datos no representativos del contexto local e interpretabilidad limitada
A37: R — RELEVANTE: ¿Por qué es importante este proyecto?
A38: Problema de negocio que resuelve | B38: Pérdida de visibilidad del tráfico por el cifrado masivo | C38: Pérdidas de cosecha por detección tardía de plagas | D38: Pérdidas económicas por fraude digital
A39: Objetivo organizacional | B39: Gestión de calidad de servicio y seguridad sin descifrar las comunicaciones | C39: Productividad agrícola | D39: Seguridad transaccional e inclusión financiera
A40: Impacto en KPIs de negocio | B40: Exactitud de clasificación y costo de inferencia por flujo | C40: Porcentaje de cosecha perdida | D40: Tasa de fraude no detectado y de falsos positivos
A41: Stakeholders beneficiados | B41: Proveedores de Internet, empresas y equipos de seguridad | C41: Productores, asociaciones y exportadores | D41: Usuarios, comercios y entidades financieras
...

Sheet Checklist P1
A1: CHECKLIST DE VALIDACIÓN DE OBJETIVOS SMART PARA IA — PROBLEMA 1 (MAYOR PUNTAJE)
A3: Proyecto: | C3: Análisis comparativo de modelos de aprendizaje automático y arquitecturas Transformer para la clasificación de tráfico de red cifrado sobre el dataset CESNET-TLS-Year22
A4: Evaluador: | C4: Jairo Wladimir Jhayya Perlaza (autoevaluación)
A5: Fecha de evaluación: | C5: 22/09/2026
A7: Se evalúan dos versiones del Problema 1: la publicada en el foro y la definitiva tras el refinamiento. Cada casilla se marca «Sí» o «No». Regla de puntuación: los máximos oficiales (5/7/7/7/5) no coinciden con el número de casillas de cada criterio, por lo que el puntaje se escala: (casillas cumplidas ÷ casillas del criterio) × máximo oficial. Los ítems propios de proyectos empresariales (ROI, adopción, compromiso formal de stakeholders) se evaluaron con rigor y no se excluyeron del cálculo.
A9: CRITERIO ESPECÍFICO (Specific) — máximo 5 puntos
A10: # | B10: Bloque | C10: Ítem del checklist oficial | D10: Versión foro | E10: Versión definitiva | F10: Evidencia / observación
A11: 1 | B11: Claridad del objetivo | C11: Define exactamente QUÉ se va a construir (no solo «implementar IA») | D11: No | E11: Sí | F11: Foro: solo «un modelo de aprendizaje profundo». Definitiva: estudio comparativo de 4 modelos y aplicación web con clasificador en vivo.
A12: 2 | B12: Claridad del objetivo | C12: Especifica el tipo de solución IA (ML, NLP, Computer Vision, etc.) | D12: Sí | E12: Sí | F12: Machine Learning supervisado (Random Forest, XGBoost) y Deep Learning (1D-CNN, Transformer encoder).
A13: 3 | B13: Claridad del objetivo | C13: Identifica usuarios finales claros y específicos | D13: Sí | E13: Sí | F13: Primarios: administradores y analistas de red de proveedores de Internet y empresas. Secundarios: investigadores y docentes.
A14: 4 | B14: Claridad del objetivo | C14: Define el alcance (qué incluye y qué NO incluye) | D14: No | E14: Sí | F14: Incluye 24 categorías, 4 modelos y la app; excluye modelos sobre contenido de paquetes, PCAP crudos, detección de intrusiones y captura propia.
A15: 5 | B15: Claridad del objetivo | C15: Describe funcionalidades principales de manera concreta | D15: No | E15: Sí | F15: Explorador de datos, arena comparativa de modelos, clasificador en vivo y carga de CSV con plantilla.
A16: Casillas cumplidas (de 5) | D16: =COUNTIF(D11:D15,"Sí") -> 2 | E16: =COUNTIF(E11:E15,"Sí") -> 5
A17: Puntuación Específico: ___/5 | D17: =ROUND(D16/COUNTA(D11:D15)*5,2) -> 2 | E17: =ROUND(E16/COUNTA(E11:E15)*5,2) -> 5 | F17: Escala: (casillas cumplidas ÷ 5) × 5
A18: Preguntas de validación (respondidas para la versión definitiva)
A19: ¿Un desarrollador externo podría entender exactamente qué construir? | D19: Sí: dataset, muestra, modelos, métricas, stack y páginas de la aplicación están nombrados de forma explícita.
A20: ¿Está libre de jerga ambigua como «optimizar», «mejorar», «automatizar»? | D20: Sí: los objetivos usan verbos verificables (construir, evaluar comparativamente, desarrollar), cada uno con su entregable.
A22: CRITERIO MEDIBLE (Measurable) — máximo 7 puntos
A23: # | B23: Bloque | C23: Ítem del checklist oficial | D23: Versión foro | E23: Versión definitiva | F23: Evidencia / observación
A24: 6 | B24: Métricas técnicas | C24: Métricas de performance del modelo (accuracy, precision, recall, F1) | D24: No | E24: Sí | F24: F1 macro (principal), F1 ponderado, exactitud, precisión y recall por clase, matriz de confusión.
A25: 7 | B25: Métricas técnicas | C25: Métricas de rendimiento técnico (latencia, throughput) | D25: No | E25: Sí | F25: Latencia de inferencia por flujo (ms), número de parámetros y tiempo de entrenamiento; el throughput no se mide por separado.
A26: 8 | B26: Métricas técnicas | C26: Baseline actual documentado para comparación | D26: No | E26: No | F26: Definido (Random Forest), pero su valor numérico se obtendrá en la semana 1 del proyecto. Es la acción inmediata.
A27: 9 | B27: Métricas técnicas | C27: Targets numéricos específicos (no rangos vagos) | D27: No | E27: Sí | F27: F1 macro ≥ 0,80 del modelo desplegado (meta inicial, recalibrable con la línea base); latencia ≤ 10 ms por flujo; α = 0,05.
A28: 10 | B28: Métricas técnicas | C28: Método de medición definido (cómo y cuándo medir) | D28: No | E28: Sí | F28: Sobre el conjunto de prueba de la partición temporal, con las mismas particiones y semillas para todos los modelos, al cierre de las semanas 2 y 3.
A29: 11 | B29: Métricas de negocio | C29: ROI calculable con números específicos | D29: No | E29: No | F29: Prototipo académico sin datos operativos: el ROI no es calculable con rigor.
A30: 12 | B30: Métricas de negocio | C30: Impacto cuantificado (ahorro de tiempo, reducción de costos) | D30: No | E30: Sí | F30: Se cuantifica el costo computacional relativo de cada modelo frente a su F1, base de la recomendación práctica.
A31: 13 | B31: Métricas de negocio | C31: Métricas de adopción (usuarios activos, transacciones procesadas) | D31: No | E31: No | F31: Sin usuarios reales dentro del alcance; la aplicación es demostrativa.
A32: Casillas cumplidas (de 8) | D32: =COUNTIF(D24:D31,"Sí") -> 0 | E32: =COUNTIF(E24:E31,"Sí") -> 5
A33: Puntuación Medible: ___/7 | D33: =ROUND(D32/COUNTA(D24:D31)*7,2) -> 0 | E33: =ROUND(E32/COUNTA(E24:E31)*7,2) -> 4.38 | F33: Escala: (casillas cumplidas ÷ 8) × 7
A34: Preguntas de validación (respondidas para la versión definitiva)
A35: ¿Cómo sabríamos si el proyecto fue exitoso en 6 meses? | D35: Si el modelo recomendado conserva su F1 macro sobre tráfico de meses posteriores (la partición temporal lo estima) y el estudio sigue siendo reproducible desde el repositorio.
A36: ¿Las métricas son objetivamente verificables? | D36: Sí: todas se recalculan desde el código publicado, con semillas fijas y particiones documentadas.
A38: CRITERIO ALCANZABLE (Achievable) — máximo 7 puntos
A39: # | B39: Bloque | C39: Ítem del checklist oficial | D39: Versión foro | E39: Versión definitiva | F39: Evidencia / observación
A40: 14 | B40: Recursos humanos | C40: Equipo técnico identificado con skills adecuados | D40: No | E40: Sí | F40: Proyecto individual: el autor, ingeniero en sistemas con experiencia en ciberseguridad, cubre data science, ML engineering y desarrollo.
A41: 15 | B41: Recursos humanos | C41: Tiempo de dedicación definido por persona | D41: No | E41: Sí | F41: Dedicación estimada de 15 horas semanales durante 5 semanas.
A42: 16 | B42: Recursos humanos | C42: Roles y responsabilidades claros | D42: No | E42: Sí | F42: El autor ejecuta el proyecto; el docente de la asignatura valida alcance y avances.
A43: 17 | B43: Recursos humanos | C43: Acceso a expertos de dominio asegurado | D43: No | E43: Sí | F43: Experiencia propia en ciberseguridad y redes, más la documentación oficial del dataset publicada en Scientific Data.
A44: 18 | B44: Recursos técnicos y datos | C44: Datos suficientes disponibles (cantidad y calidad) | D44: Sí | E44: Sí | F44: Millones de flujos etiquetados de una red de producción; la muestra XS supera ampliamente los 10.000 registros.
A45: 19 | B45: Recursos técnicos y datos | C45: Infraestructura técnica adecuada o planificada | D45: No | E45: Sí | F45: Laptop para modelos clásicos y la app; GPU gratuita en Google Colab o Kaggle para las redes profundas.
...

Sheet Refinamiento P1
A1: REFINAMIENTO DEL PROBLEMA 1: DEL FORO A LA VERSIÓN DEFINITIVA
A3: Aspecto | B3: Versión publicada en el foro | C3: Versión definitiva | D3: Motivo del ajuste
A4: Tarea | B4: Clasificación de tráfico cifrado para detección de intrusiones (dos tareas). | C4: Clasificación de tráfico cifrado por 24 categorías de servicio (una tarea). | D4: Mejora ESPECÍFICO y TEMPORAL: una sola tarea es abordable en el plazo.
A5: Dataset | B5: CIC-IDS2017 o CESNET-TLS22. | C5: CESNET-TLS-Year22 (2024), muestra XS mediante cesnet-datazoo. | D5: Dataset más reciente con publicación formal; cubre un año completo y permite partición temporal.
A6: Características | B6: Tamaños de paquete, tiempos entre llegadas, duración y entropía. | C6: Secuencias de los primeros 30 paquetes (tamaño, dirección, tiempo) y estadísticas de flujo. | D6: El dataset no incluye el contenido de los paquetes; la entropía de bytes no es calculable.
A7: Técnica de IA | B7: Un modelo de aprendizaje profundo. | C7: Comparativa: Random Forest, XGBoost, 1D-CNN y Transformer encoder. | D7: Aporta línea base y responde una pregunta concreta: desempeño frente a costo.
A8: Evaluación | B8: No definida. | C8: F1 macro y ponderado, exactitud, matriz de confusión, latencia, parámetros, tiempo de entrenamiento y McNemar (α = 0,05). | D8: Mejora MEDIBLE: criterios de éxito y de decisión explícitos.
A9: Entregable | B9: No definido. | C9: Aplicación web Streamlit desplegada con URL pública. | D9: Resultados demostrables y ejecutables.
A10: Plazo | B10: No definido. | C10: Cinco semanas con un hito verificable por semana. | D10: Mejora TEMPORAL.
A13: OBJETIVOS DEFINITIVOS
A14: Título | B14: Análisis comparativo de modelos de aprendizaje automático y arquitecturas Transformer para la clasificación de tráfico de red cifrado sobre el dataset CESNET-TLS-Year22.
A15: Objetivo general | B15: Desarrollar un estudio comparativo entre modelos clásicos de aprendizaje automático y arquitecturas profundas basadas en atención para la clasificación de tráfico de red cifrado por categorías de servicio sobre el dataset CESNET-TLS-Year22, evaluando desempeño y costo computacional bajo partición temporal, y disponibilizando los resultados mediante una aplicación web interactiva.
A16: OE1 (semana 1) | B16: Construir el conjunto experimental de trabajo a partir del dataset CESNET-TLS-Year22, mediante la selección de la muestra (tamaño XS), la partición temporal de los datos y el análisis exploratorio de las 24 categorías de servicio, para garantizar condiciones idénticas y reproducibles de entrenamiento y evaluación para todos los modelos.
A17: OE2 (semanas 2-3) | B17: Evaluar comparativamente el desempeño y el costo computacional de cuatro modelos de clasificación —Random Forest, XGBoost, red convolucional 1D y Transformer encoder— mediante métricas de desempeño (F1 macro y ponderado, exactitud, matriz de confusión), métricas de costo (latencia de inferencia, número de parámetros, tiempo de entrenamiento) y la prueba de McNemar (α = 0,05), para determinar qué familia de modelos ofrece el mejor equilibrio en la clasificación de tráfico cifrado.
A18: OE3 (semanas 4-5) | B18: Desarrollar una aplicación web interactiva en Streamlit que integre la exploración del dataset, la comparativa de modelos y la clasificación de flujos en tiempo real con el mejor modelo, para demostrar de forma ejecutable y verificable los resultados del estudio.
A20: Letra SMART | B20: Cómo lo cumple el objetivo general
A21: S — Específico | B21: Una tarea (clasificación por categorías de servicio), un dataset (CESNET-TLS-Year22) y cuatro modelos nombrados.
A22: M — Medible | B22: F1 macro como métrica principal, métricas de costo y prueba de McNemar con α = 0,05.
A23: A — Alcanzable | B23: Datos abiertos en muestra XS, modelos ligeros, GPU gratuita en Colab o Kaggle y stack 100 % Python.
A24: R — Relevante | B24: Responde a la pérdida de visibilidad por el cifrado masivo del tráfico con técnicas actuales de IA.
A25: T — Temporal | B25: Cinco semanas con un hito verificable por semana y holgura en la semana de cierre.
